[2022-08-04 16:28:52,029] {taskinstance.py:670} INFO - Dependencies all met for <TaskInstance: twitter_dag.twitter_flamengomalvadao 2022-08-02T09:00:00+00:00 [queued]>
[2022-08-04 16:28:52,041] {taskinstance.py:670} INFO - Dependencies all met for <TaskInstance: twitter_dag.twitter_flamengomalvadao 2022-08-02T09:00:00+00:00 [queued]>
[2022-08-04 16:28:52,041] {taskinstance.py:880} INFO - 
--------------------------------------------------------------------------------
[2022-08-04 16:28:52,041] {taskinstance.py:881} INFO - Starting attempt 3 of 3
[2022-08-04 16:28:52,041] {taskinstance.py:882} INFO - 
--------------------------------------------------------------------------------
[2022-08-04 16:28:52,473] {taskinstance.py:901} INFO - Executing <Task(TwitterOperator): twitter_flamengomalvadao> on 2022-08-02T09:00:00+00:00
[2022-08-04 16:28:52,479] {standard_task_runner.py:54} INFO - Started process 146030 to run task
[2022-08-04 16:28:52,541] {standard_task_runner.py:77} INFO - Running: ['airflow', 'run', 'twitter_dag', 'twitter_flamengomalvadao', '2022-08-02T09:00:00+00:00', '--job_id', '68', '--pool', 'default_pool', '--raw', '-sd', 'DAGS_FOLDER/twitter_dag.py', '--cfg_path', '/tmp/tmpt640yce8']
[2022-08-04 16:28:52,542] {standard_task_runner.py:78} INFO - Job 68: Subtask twitter_flamengomalvadao
[2022-08-04 16:28:52,949] {logging_mixin.py:112} INFO - Running <TaskInstance: twitter_dag.twitter_flamengomalvadao 2022-08-02T09:00:00+00:00 [running]> on host ama
[2022-08-04 16:28:52,967] {taskinstance.py:1150} ERROR - [Errno 13] Permission denied: '/airflow-pipeline-alura'
Traceback (most recent call last):
  File "/usr/lib/python3.8/pathlib.py", line 1288, in mkdir
    self._accessor.mkdir(self, mode)
FileNotFoundError: [Errno 2] No such file or directory: '/airflow-pipeline-alura/datapipeline/datalake/bronze/twitter_flamengomalvadao/extract_date=2022-08-02'

During handling of the above exception, another exception occurred:

Traceback (most recent call last):
  File "/usr/lib/python3.8/pathlib.py", line 1288, in mkdir
    self._accessor.mkdir(self, mode)
FileNotFoundError: [Errno 2] No such file or directory: '/airflow-pipeline-alura/datapipeline/datalake/bronze/twitter_flamengomalvadao'

During handling of the above exception, another exception occurred:

Traceback (most recent call last):
  File "/usr/lib/python3.8/pathlib.py", line 1288, in mkdir
    self._accessor.mkdir(self, mode)
FileNotFoundError: [Errno 2] No such file or directory: '/airflow-pipeline-alura/datapipeline/datalake/bronze'

During handling of the above exception, another exception occurred:

Traceback (most recent call last):
  File "/usr/lib/python3.8/pathlib.py", line 1288, in mkdir
    self._accessor.mkdir(self, mode)
FileNotFoundError: [Errno 2] No such file or directory: '/airflow-pipeline-alura/datapipeline/datalake'

During handling of the above exception, another exception occurred:

Traceback (most recent call last):
  File "/usr/lib/python3.8/pathlib.py", line 1288, in mkdir
    self._accessor.mkdir(self, mode)
FileNotFoundError: [Errno 2] No such file or directory: '/airflow-pipeline-alura/datapipeline'

During handling of the above exception, another exception occurred:

Traceback (most recent call last):
  File "/home/amadeus/ama/airflow-pipeline-alura/datapipeline/.env/lib/python3.8/site-packages/airflow/models/taskinstance.py", line 984, in _run_raw_task
    result = task_copy.execute(context=context)
  File "/home/amadeus/ama/airflow-pipeline-alura/datapipeline/airflow/plugins/operators/twitter_operator.py", line 48, in execute
    self.create_parent_folder()
  File "/home/amadeus/ama/airflow-pipeline-alura/datapipeline/airflow/plugins/operators/twitter_operator.py", line 38, in create_parent_folder
    Path(Path(self.file_path).parent).mkdir(parents=True, exist_ok=True) # Cria a pasta e verifica sub-pastas existentes
  File "/usr/lib/python3.8/pathlib.py", line 1292, in mkdir
    self.parent.mkdir(parents=True, exist_ok=True)
  File "/usr/lib/python3.8/pathlib.py", line 1292, in mkdir
    self.parent.mkdir(parents=True, exist_ok=True)
  File "/usr/lib/python3.8/pathlib.py", line 1292, in mkdir
    self.parent.mkdir(parents=True, exist_ok=True)
  [Previous line repeated 2 more times]
  File "/usr/lib/python3.8/pathlib.py", line 1288, in mkdir
    self._accessor.mkdir(self, mode)
PermissionError: [Errno 13] Permission denied: '/airflow-pipeline-alura'
[2022-08-04 16:28:52,968] {taskinstance.py:1187} INFO - Marking task as FAILED. dag_id=twitter_dag, task_id=twitter_flamengomalvadao, execution_date=20220802T090000, start_date=20220804T192852, end_date=20220804T192852
[2022-08-04 16:28:56,801] {local_task_job.py:102} INFO - Task exited with return code 1
